Workbook

Sheet Raw Data
A1: index | B1: Sample Name | C1: Site Name | D1: Turbidity | E1: TSS | F1: TP | G1: TN | H1: reflectance_400_nm | I1: reflectance_402_nm | J1: reflectance_404_nm | K1: reflectance_406_nm | L1: reflectance_408_nm | M1: reflectance_410_nm | N1: reflectance_412_nm | O1: reflectance_414_nm | P1: reflectance_416_nm | Q1: reflectance_418_nm | R1: reflectance_420_nm | S1: reflectance_422_nm | T1: reflectance_424_nm | U1: reflectance_426_nm | V1: reflectance_428_nm | W1: reflectance_430_nm | X1: reflectance_432_nm | Y1: reflectance_434_nm | Z1: reflectance_436_nm | AA1: reflectance_438_nm | AB1: reflectance_440_nm | AC1: reflectance_442_nm | AD1: reflectance_444_nm | AE1: reflectance_446_nm | AF1: reflectance_448_nm | AG1: reflectance_450_nm | AH1: reflectance_452_nm | AI1: reflectance_454_nm | AJ1: reflectance_456_nm | AK1: reflectance_458_nm | AL1: reflectance_460_nm | AM1: reflectance_462_nm | AN1: reflectance_464_nm | AO1: reflectance_466_nm | AP1: reflectance_468_nm | AQ1: reflectance_470_nm | AR1: reflectance_472_nm | AS1: reflectance_474_nm | AT1: reflectance_476_nm | AU1: reflectance_478_nm | AV1: reflectance_480_nm | AW1: reflectance_482_nm | AX1: reflectance_484_nm | AY1: reflectance_486_nm | AZ1: reflectance_488_nm | BA1: reflectance_490_nm | BB1: reflectance_492_nm | BC1: reflectance_494_nm | BD1: reflectance_496_nm | BE1: reflectance_498_nm | BF1: reflectance_500_nm | BG1: reflectance_502_nm | BH1: reflectance_504_nm | BI1: reflectance_506_nm | BJ1: reflectance_508_nm | BK1: reflectance_510_nm | BL1: reflectance_512_nm | BM1: reflectance_514_nm | BN1: reflectance_516_nm | BO1: reflectance_518_nm | BP1: reflectance_520_nm | BQ1: reflectance_522_nm | BR1: reflectance_524_nm | BS1: reflectance_526_nm | BT1: reflectance_528_nm | BU1: reflectance_530_nm | BV1: reflectance_532_nm | BW1: reflectance_534_nm | BX1: reflectance_536_nm | BY1: reflectance_538_nm | BZ1: reflectance_540_nm | CA1: reflectance_542_nm | CB1: reflectance_544_nm | CC1: reflectance_546_nm | CD1: reflectance_548_nm | CE1: reflectance_550_nm | CF1: reflectance_552_nm | CG1: reflectance_554_nm | CH1: reflectance_556_nm | CI1: reflectance_558_nm | CJ1: reflectance_560_nm | CK1: reflectance_562_nm | CL1: reflectance_564_nm | CM1: reflectance_566_nm | CN1: reflectance_568_nm | CO1: reflectance_570_nm | CP1: reflectance_572_nm | CQ1: reflectance_574_nm | CR1: reflectance_576_nm | CS1: reflectance_578_nm | CT1: reflectance_580_nm | CU1: reflectance_582_nm | CV1: reflectance_584_nm | CW1: reflectance_586_nm | CX1: reflectance_588_nm | CY1: reflectance_590_nm | CZ1: reflectance_592_nm | DA1: reflectance_594_nm | DB1: reflectance_596_nm | DC1: reflectance_598_nm | DD1: reflectance_600_nm | DE1: reflectance_602_nm | DF1: reflectance_604_nm | DG1: reflectance_606_nm | DH1: reflectance_608_nm | DI1: reflectance_610_nm | DJ1: reflectance_612_nm | DK1: reflectance_614_nm | DL1: reflectance_616_nm | DM1: reflectance_618_nm | DN1: reflectance_620_nm | DO1: reflectance_622_nm | DP1: reflectance_624_nm | DQ1: reflectance_626_nm | DR1: reflectance_628_nm | DS1: reflectance_630_nm | DT1: reflectance_632_nm | DU1: reflectance_634_nm | DV1: reflectance_636_nm | DW1: reflectance_638_nm | DX1: reflectance_640_nm | DY1: reflectance_642_nm | DZ1: reflectance_644_nm | EA1: reflectance_646_nm | EB1: reflectance_648_nm | EC1: reflectance_650_nm | ED1: reflectance_652_nm | EE1: reflectance_654_nm | EF1: reflectance_656_nm | EG1: reflectance_658_nm | EH1: reflectance_660_nm | EI1: reflectance_662_nm | EJ1: reflectance_664_nm | EK1: reflectance_666_nm | EL1: reflectance_668_nm | EM1: reflectance_670_nm | EN1: reflectance_672_nm | EO1: reflectance_674_nm | EP1: reflectance_676_nm | EQ1: reflectance_678_nm | ER1: reflectance_680_nm | ES1: reflectance_682_nm | ET1: reflectance_684_nm | EU1: reflectance_686_nm | EV1: reflectance_688_nm | EW1: reflectance_690_nm | EX1: reflectance_692_nm | EY1: reflectance_694_nm | EZ1: reflectance_696_nm | FA1: reflectance_698_nm | FB1: reflectance_700_nm | FC1: reflectance_702_nm | FD1: reflectance_704_nm | FE1: reflectance_706_nm | FF1: reflectance_708_nm | FG1: reflectance_710_nm | FH1: reflectance_712_nm | FI1: reflectance_714_nm | FJ1: reflectance_716_nm | FK1: reflectance_718_nm | FL1: reflectance_720_nm | FM1: reflectance_722_nm | FN1: reflectance_724_nm | FO1: reflectance_726_nm | FP1: reflectance_728_nm | FQ1: reflectance_730_nm | FR1: reflectance_732_nm | FS1: reflectance_734_nm | FT1: reflectance_736_nm | FU1: reflectance_738_nm | FV1: reflectance_740_nm | FW1: reflectance_742_nm | FX1: reflectance_744_nm | FY1: reflectance_746_nm | FZ1: reflectance_748_nm | GA1: reflectance_750_nm | GB1: reflectance_752_nm | GC1: reflectance_754_nm | GD1: reflectance_756_nm | GE1: reflectance_758_nm | GF1: reflectance_760_nm | GG1: reflectance_762_nm | GH1: reflectance_764_nm | GI1: reflectance_766_nm | GJ1: reflectance_768_nm | GK1: reflectance_770_nm | GL1: reflectance_772_nm | GM1: reflectance_774_nm | GN1: reflectance_776_nm | GO1: reflectance_778_nm | GP1: reflectance_780_nm | GQ1: reflectance_782_nm | GR1: reflectance_784_nm | GS1: reflectance_786_nm | GT1: reflectance_788_nm | GU1: reflectance_790_nm | GV1: reflectance_792_nm | GW1: reflectance_794_nm | GX1: reflectance_796_nm | GY1: reflectance_798_nm | GZ1: reflectance_800_nm | HA1: reflectance_802_nm | HB1: reflectance_804_nm | HC1: reflectance_806_nm | HD1: reflectance_808_nm | HE1: reflectance_810_nm | HF1: reflectance_812_nm | HG1: reflectance_814_nm | HH1: reflectance_816_nm | HI1: reflectance_818_nm | HJ1: reflectance_820_nm | HK1: reflectance_822_nm | HL1: reflectance_824_nm | HM1: reflectance_826_nm | HN1: reflectance_828_nm | HO1: reflectance_830_nm | HP1: reflectance_832_nm | HQ1: reflectance_834_nm | HR1: reflectance_836_nm | HS1: reflectance_838_nm | HT1: reflectance_840_nm | HU1: reflectance_842_nm | HV1: reflectance_844_nm | HW1: reflectance_846_nm | HX1: reflectance_848_nm | HY1: reflectance_850_nm | HZ1: reflectance_852_nm | IA1: reflectance_854_nm | IB1: reflectance_856_nm | IC1: reflectance_858_nm | ID1: reflectance_860_nm | IE1: reflectance_862_nm | IF1: reflectance_864_nm | IG1: reflectance_866_nm | IH1: reflectance_868_nm | II1: reflectance_870_nm | IJ1: reflectance_872_nm | IK1: reflectance_874_nm | IL1: reflectance_876_nm | IM1: reflectance_878_nm | IN1: reflectance_880_nm | IO1: reflectance_882_nm | IP1: reflectance_884_nm | IQ1: reflectance_886_nm | IR1: reflectance_888_nm | IS1: reflectance_890_nm | IT1: reflectance_892_nm | IU1: reflectance_894_nm | IV1: reflectance_896_nm | IW1: reflectance_898_nm | IX1: reflectance_900_nm | IY1: reflectance_902_nm | IZ1: reflectance_904_nm | JA1: reflectance_906_nm | JB1: reflectance_908_nm | JC1: reflectance_910_nm | JD1: reflectance_912_nm | JE1: reflectance_914_nm | JF1: reflectance_916_nm | JG1: reflectance_918_nm | JH1: reflectance_920_nm | JI1: reflectance_922_nm | JJ1: reflectance_924_nm | JK1: reflectance_926_nm | JL1: reflectance_928_nm | JM1: reflectance_930_nm | JN1: reflectance_932_nm | JO1: reflectance_934_nm | JP1: reflectance_936_nm | JQ1: reflectance_938_nm | JR1: reflectance_940_nm | JS1: reflectance_942_nm | JT1: reflectance_944_nm | JU1: reflectance_946_nm | JV1: reflectance_948_nm | JW1: reflectance_950_nm | JX1: reflectance_952_nm | JY1: reflectance_954_nm | JZ1: reflectance_956_nm | KA1: reflectance_958_nm | KB1: reflectance_960_nm | KC1: reflectance_962_nm | KD1: reflectance_964_nm | KE1: reflectance_966_nm | KF1: reflectance_968_nm | KG1: reflectance_970_nm | KH1: reflectance_972_nm | KI1: reflectance_974_nm | KJ1: reflectance_976_nm | KK1: reflectance_978_nm | KL1: reflectance_980_nm | KM1: reflectance_982_nm | KN1: reflectance_984_nm | KO1: reflectance_986_nm | KP1: reflectance_988_nm | KQ1: reflectance_990_nm | KR1: reflectance_992_nm | KS1: reflectance_994_nm | KT1: reflectance_996_nm | KU1: reflectance_998_nm | KV1: reflectance_1000_nm
A2: 1 | B2: R001 | C2: PAK | D2: 209.5 | F2: 12 | G2: 91 | H2: 0.013848036 | I2: 0.013750728 | J2: 0.013757813 | K2: 0.013777011 | L2: 0.013718989 | M2: 0.013640308 | N2: 0.013599958 | O2: 0.013618126 | P2: 0.013652999 | Q2: 0.013652302 | R2: 0.013585968 | S2: 0.01345593 | T2: 0.013327084 | U2: 0.013204298 | V2: 0.013142129 | W2: 0.01308278 | X2: 0.01305459 | Y2: 0.013033219 | Z2: 0.013030368 | AA2: 0.013061034 | AB2: 0.013079132 | AC2: 0.013152289 | AD2: 0.013163223 | AE2: 0.013224049 | AF2: 0.013253963 | AG2: 0.013281967 | AH2: 0.013310122 | AI2: 0.01332945 | AJ2: 0.01337693 | AK2: 0.013374358 | AL2: 0.01341913 | AM2: 0.01342033 | AN2: 0.013453768 | AO2: 0.013483413 | AP2: 0.013497781 | AQ2: 0.01353254 | AR2: 0.013515177 | AS2: 0.013543075 | AT2: 0.013522634 | AU2: 0.013518177 | AV2: 0.013503536 | AW2: 0.013478457 | AX2: 0.01347645 | AY2: 0.01346093 | AZ2: 0.013491259 | BA2: 0.013491843 | BB2: 0.013550299 | BC2: 0.01361249 | BD2: 0.013684852 | BE2: 0.013773968 | BF2: 0.013852065 | BG2: 0.013952988 | BH2: 0.014027879 | BI2: 0.014109303 | BJ2: 0.014159176 | BK2: 0.014212229 | BL2: 0.014258224 | BM2: 0.014294918 | BN2: 0.01433372 | BO2: 0.014345882 | BP2: 0.014338758 | BQ2: 0.014302724 | BR2: 0.014305 | BS2: 0.014329628 | BT2: 0.014331341 | BU2: 0.014318893 | BV2: 0.014280819 | BW2: 0.014269848 | BX2: 0.014239728 | BY2: 0.014218937 | BZ2: 0.014187088 | CA2: 0.014169465 | CB2: 0.014155614 | CC2: 0.014133956 | CD2: 0.014121578 | CE2: 0.014079871 | CF2: 0.014051724 | CG2: 0.01401422 | CH2: 0.013986173 | CI2: 0.013957914 | CJ2: 0.013913048 | CK2: 0.013889651 | CL2: 0.013832993 | CM2: 0.013816835 | CN2: 0.013774725 | CO2: 0.013743575 | CP2: 0.013716979 | CQ2: 0.01367989 | CR2: 0.013664257 | CS2: 0.013621414 | CT2: 0.013605974 | CU2: 0.013564676 | CV2: 0.013537234 | CW2: 0.013508166 | CX2: 0.013475335 | CY2: 0.013444013 | CZ2: 0.013389482 | DA2: 0.013359739 | DB2: 0.013313476 | DC2: 0.013279229 | DD2: 0.013224434 | DE2: 0.013184175 | DF2: 0.01315519 | DG2: 0.013085093 | DH2: 0.013065473 | DI2: 0.013013985 | DJ2: 0.012988609 | DK2: 0.012946247 | DL2: 0.012897501 | DM2: 0.012861762 | DN2: 0.012808922 | DO2: 0.012805245 | DP2: 0.012757137 | DQ2: 0.012749605 | DR2: 0.012716845 | DS2: 0.012699221 | DT2: 0.012682437 | DU2: 0.01265925 | DV2: 0.012671396 | DW2: 0.012654324 | DX2: 0.012672936 | DY2: 0.012656464 | DZ2: 0.012664603 | EA2: 0.012669925 | EB2: 0.012671401 | EC2: 0.012694131 | ED2: 0.012674707 | EE2: 0.012691488 | EF2: 0.012666866 | EG2: 0.012682015 | EH2: 0.012686555 | EI2: 0.012673422 | EJ2: 0.012686301 | EK2: 0.012675654 | EL2: 0.012722906 | EM2: 0.012707139 | EN2: 0.012769974 | EO2: 0.012813241 | EP2: 0.012874161 | EQ2: 0.012943309 | ER2: 0.012968579 | ES2: 0.01302991 | ET2: 0.013031364 | EU2: 0.013050911 | EV2: 0.013027338 | EW2: 0.012983328 | EX2: 0.012941747 | EY2: 0.01288663 | EZ2: 0.012876975 | FA2: 0.012847307 | FB2: 0.012829969 | FC2: 0.012759337 | FD2: 0.012748659 | FE2: 0.012731399 | FF2: 0.012670153 | FG2: 0.012628872 | FH2: 0.012555701 | FI2: 0.012533545 | FJ2: 0.012468752 | FK2: 0.012426256 | FL2: 0.012359822 | FM2: 0.01228196 | FN2: 0.012216053 | FO2: 0.012113588 | FP2: 0.012042262 | FQ2: 0.011907385 | FR2: 0.011817552 | FS2: 0.011713149 | FT2: 0.011602275 | FU2: 0.011523983 | FV2: 0.011481996 | FW2: 0.01146083 | FX2: 0.011416791 | FY2: 0.011414294 | FZ2: 0.011411668 | GA2: 0.011396506 | GB2: 0.011372554 | GC2: 0.011344284 | GD2: 0.0113478 | GE2: 0.011265974 | GF2: 0.011274887 | GG2: 0.011233962 | GH2: 0.011247208 | GI2: 0.011261487 | GJ2: 0.011285249 | GK2: 0.011306267 | GL2: 0.011285417 | GM2: 0.011313138 | GN2: 0.011311648 | GO2: 0.011326493 | GP2: 0.011336095 | GQ2: 0.011344677 | GR2: 0.011362133 | GS2: 0.011359825 | GT2: 0.011388599 | GU2: 0.011407611 | GV2: 0.01143952 | GW2: 0.011454723 | GX2: 0.011466117 | GY2: 0.011493705 | GZ2: 0.011512578 | HA2: 0.011550613 | HB2: 0.011572671 | HC2: 0.011603317 | HD2: 0.011607392 | HE2: 0.011627368 | HF2: 0.011648697 | HG2: 0.011641316 | HH2: 0.011648703 | HI2: 0.011708051 | HJ2: 0.011714455 | HK2: 0.011656352 | HL2: 0.011623257 | HM2: 0.011558309 | HN2: 0.01153808 | HO2: 0.011483478 | HP2: 0.011408787 | HQ2: 0.011350745 | HR2: 0.01133669 | HS2: 0.011312374 | HT2: 0.011241322 | HU2: 0.011240739 | HV2: 0.01121663 | HW2: 0.011146585 | HX2: 0.011144778 | HY2: 0.011184722 | HZ2: 0.011173376 | IA2: 0.011126732 | IB2: 0.011080377 | IC2: 0.011026288 | ID2: 0.011056532 | IE2: 0.011059211 | IF2: 0.010991209 | IG2: 0.010954757 | IH2: 0.010921741 | II2: 0.010850868 | IJ2: 0.010777955 | IK2: 0.01065433 | IL2: 0.010549928 | IM2: 0.010565513 | IN2: 0.010464391 | IO2: 0.010365885 | IP2: 0.01026866 | IQ2: 0.010171016 | IR2: 0.010104998 | IS2: 0.010021357 | IT2: 0.0098848533 | IU2: 0.009773929 | IV2: 0.0097079492 | IW2: 0.0096049484 | IX2: 0.0094758724 | IY2: 0.0092923714 | IZ2: 0.0091068541 | JA2: 0.0089787045 | JB2: 0.0087502005 | JC2: 0.0085510796 | JD2: 0.0084159365 | JE2: 0.0082816568 | JF2: 0.0081444118 | JG2: 0.0080525949 | JH2: 0.0080339221 | JI2: 0.0080629427 | JJ2: 0.0081815417 | JK2: 0.008286437 | JL2: 0.0083369474 | JM2: 0.0084226736 | JN2: 0.0084539939 | JO2: 0.0084621086 | JP2: 0.0084381469 | JQ2: 0.0083103867 | JR2: 0.0081977493 | JS2: 0.008073686 | JT2: 0.0079187822 | JU2: 0.0077368033 | JV2: 0.0074744207 | JW2: 0.0071854145 | JX2: 0.0070090796 | JY2: 0.0067241736 | JZ2: 0.0064835674 | KA2: 0.0062414154 | KB2: 0.0060361567 | KC2: 0.0059300103 | KD2: 0.005836607 | KE2: 0.0057840378 | KF2: 0.005760387 | KG2: 0.0057500645 | KH2: 0.0058293608 | KI2: 0.00603327 | KJ2: 0.0063146227 | KK2: 0.0067330896 | KL2: 0.0073345062 | KM2: 0.0080938178 | KN2: 0.0092223435 | KO2: 0.010416212 | KP2: 0.011875189 | KQ2: 0.01344613 | KR2: 0.015047338 | KS2: 0.016717978 | KT2: 0.01822425 | KU2: 0.019601072 | KV2: 0.020933554
A3: 2 | B3: R002 | C3: PAK | D3: 167 | E3: 86.206897 | F3: 13 | G3: 64.8 | H3: 0.014123659 | I3: 0.014034223 | J3: 0.014041325 | K3: 0.014075154 | L3: 0.014067637 | M3: 0.014007393 | N3: 0.013876975 | O3: 0.013900978 | P3: 0.01394664 | Q3: 0.013976186 | R3: 0.013892529 | S3: 0.013744874 | T3: 0.013571738 | U3: 0.013420106 | V3: 0.013326731 | W3: 0.01321358 | X3: 0.013175097 | Y3: 0.013138836 | Z3: 0.013134864 | AA3: 0.013165111 | AB3: 0.013192729 | AC3: 0.013250535 | AD3: 0.013255135 | AE3: 0.013316565 | AF3: 0.013337778 | AG3: 0.01336478 | AH3: 0.013395477 | AI3: 0.013407455 | AJ3: 0.013447622 | AK3: 0.013451064 | AL3: 0.013498401 | AM3: 0.013509939 | AN3: 0.013556925 | AO3: 0.013597588 | AP3: 0.013621595 | AQ3: 0.013667871 | AR3: 0.013673369 | AS3: 0.013701834 | AT3: 0.013679971 | AU3: 0.013688802 | AV3: 0.01368384 | AW3: 0.013667031 | AX3: 0.013671298 | AY3: 0.013664234 | AZ3: 0.013702087 | BA3: 0.013737345 | BB3: 0.013817927 | BC3: 0.013889406 | BD3: 0.013974878 | BE3: 0.014079053 | BF3: 0.014176437 | BG3: 0.014299553 | BH3: 0.014392816 | BI3: 0.014489458 | BJ3: 0.014561117 | BK3: 0.014633529 | BL3: 0.014697914 | BM3: 0.014745669 | BN3: 0.014801278 | BO3: 0.01484524 | BP3: 0.014854845 | BQ3: 0.01484656 | BR3: 0.014866164 | BS3: 0.014902395 | BT3: 0.014941374 | BU3: 0.014969854 | BV3: 0.014955509 | BW3: 0.014963448 | BX3: 0.014948588 | BY3: 0.014943927 | BZ3: 0.014931943 | CA3: 0.014934267 | CB3: 0.014942685 | CC3: 0.014923919 | CD3: 0.014927971 | CE3: 0.014907852 | CF3: 0.014902314 | CG3: 0.014882485 | CH3: 0.014863058 | CI3: 0.014848416 | CJ3: 0.014815901 | CK3: 0.014807446 | CL3: 0.014777872 | CM3: 0.014764357 | CN3: 0.01473451 | CO3: 0.014724055 | CP3: 0.014711047 | CQ3: 0.014683237 | CR3: 0.014675751 | CS3: 0.01464633 | CT3: 0.014642781 | CU3: 0.014619182 | CV3: 0.014604288 | CW3: 0.014584917 | CX3: 0.014562319 | CY3: 0.01454169 | CZ3: 0.014504982 | DA3: 0.014475955 | DB3: 0.014419998 | DC3: 0.014394508 | DD3: 0.014353066 | DE3: 0.014311978 | DF3: 0.014291059 | DG3: 0.014237853 | DH3: 0.014223958 | DI3: 0.014163878 | DJ3: 0.014139648 | DK3: 0.014092858 | DL3: 0.014059113 | DM3: 0.014036047 | DN3: 0.013996381 | DO3: 0.014002005 | DP3: 0.013965934 | DQ3: 0.013966284 | DR3: 0.01394457 | DS3: 0.013941711 | DT3: 0.013939912 | DU3: 0.013927586 | DV3: 0.013950755 | DW3: 0.013913859 | DX3: 0.01393126 | DY3: 0.013903394 | DZ3: 0.013922812 | EA3: 0.013939211 | EB3: 0.013935789 | EC3: 0.013966046 | ED3: 0.013940253 | EE3: 0.013966098 | EF3: 0.013938488 | EG3: 0.013951101 | EH3: 0.013950724 | EI3: 0.013935157 | EJ3: 0.013946083 | EK3: 0.013920975 | EL3: 0.013972124 | EM3: 0.013984464 | EN3: 0.014039937 | EO3: 0.014060647 | EP3: 0.014095989 | EQ3: 0.014136222 | ER3: 0.014146537 | ES3: 0.014187869 | ET3: 0.014159198 | EU3: 0.014158731 | EV3: 0.014121898 | EW3: 0.014090388 | EX3: 0.014058968 | EY3: 0.014032566 | EZ3: 0.014039322 | FA3: 0.013990203 | FB3: 0.013996893 | FC3: 0.013967296 | FD3: 0.013941644 | FE3: 0.013909769 | FF3: 0.013862956 | FG3: 0.013826823 | FH3: 0.01377202 | FI3: 0.013758501 | FJ3: 0.013699442 | FK3: 0.01366428 | FL3: 0.013594258 | FM3: 0.013515535 | FN3: 0.013446413 | FO3: 0.013336572 | FP3: 0.013259235 | FQ3: 0.013134174 | FR3: 0.013047532 | FS3: 0.01293712 | FT3: 0.012831808 | FU3: 0.012758816 | FV3: 0.012701509 | FW3: 0.012686255 | FX3: 0.012667982 | FY3: 0.012651203 | FZ3: 0.012633267 | GA3: 0.012611874 | GB3: 0.012587364 | GC3: 0.012555676 | GD3: 0.012566454 | GE3: 0.012526926 | GF3: 0.012537116 | GG3: 0.012534186 | GH3: 0.012525298 | GI3: 0.012496718 | GJ3: 0.012486377 | GK3: 0.012496821 | GL3: 0.012497013 | GM3: 0.012523352 | GN3: 0.012526928 | GO3: 0.012523748 | GP3: 0.012518935 | GQ3: 0.0125129 | GR3: 0.01252528 | GS3: 0.012531175 | GT3: 0.012557085 | GU3: 0.01256083 | GV3: 0.012594146 | GW3: 0.012606465 | GX3: 0.012648459 | GY3: 0.012698495 | GZ3: 0.012696442 | HA3: 0.012726347 | HB3: 0.012739175 | HC3: 0.012777723 | HD3: 0.012771794 | HE3: 0.012777513 | HF3: 0.012807569 | HG3: 0.012850372 | HH3: 0.012875346 | HI3: 0.012847362 | HJ3: 0.012853972 | HK3: 0.012778385 | HL3: 0.012796129 | HM3: 0.012730899 | HN3: 0.012632471 | HO3: 0.012580665 | HP3: 0.012471519 | HQ3: 0.012409855 | HR3: 0.012386781 | HS3: 0.01239292 | HT3: 0.01238398 | HU3: 0.012360779 | HV3: 0.012328929 | HW3: 0.012316906 | HX3: 0.012305874 | HY3: 0.012285367 | HZ3: 0.01227695 | IA3: 0.012253911 | IB3: 0.012207724 | IC3: 0.012167704 | ID3: 0.012119936 | IE3: 0.012084243 | IF3: 0.012032039 | IG3: 0.011978569 | IH3: 0.011859843 | II3: 0.011794637 | IJ3: 0.011724909 | IK3: 0.011604711 | IL3: 0.011514633 | IM3: 0.011393866 | IN3: 0.011301895 | IO3: 0.011256693 | IP3: 0.011116067 | IQ3: 0.010958947 | IR3: 0.010903542 | IS3: 0.010825349 | IT3: 0.010737145 | IU3: 0.010617123 | IV3: 0.010467701 | IW3: 0.010370432 | IX3: 0.010267403 | IY3: 0.01005182 | IZ3: 0.00985149 | JA3: 0.0097248937 | JB3: 0.0094838093 | JC3: 0.0093268146 | JD3: 0.0091687355 | JE3: 0.0090187163 | JF3: 0.0089214174 | JG3: 0.0088919995 | JH3: 0.0088329131 | JI3: 0.0088631584 | JJ3: 0.0089753179 | JK3: 0.0090772207 | JL3: 0.0092322649 | JM3: 0.0093404419 | JN3: 0.0093545891 | JO3: 0.0093221843 | JP3: 0.0092970637 | JQ3: 0.0092340789 | JR3: 0.0090876762 | JS3: 0.0088240906 | JT3: 0.0087093834 | JU3: 0.0086123115 | JV3: 0.0084516622 | JW3: 0.0082346075 | JX3: 0.007965206 | JY3: 0.0076461165 | JZ3: 0.0073723672 | KA3: 0.007164208 | KB3: 0.0070162467 | KC3: 0.0068885868 | KD3: 0.0067819692 | KE3: 0.0066944616 | KF3: 0.006668209 | KG3: 0.0066859631 | KH3: 0.0067537327 | KI3: 0.0069014943 | KJ3: 0.0071764899 | KK3: 0.0076071526 | KL3: 0.0082752464 | KM3: 0.0090293063 | KN3: 0.0099662412 | KO3: 0.011122459 | KP3: 0.012544253 | KQ3: 0.014213566 | KR3: 0.015952522 | KS3: 0.017732424 | KT3: 0.019314735 | KU3: 0.021004952 | KV3: 0.022203906
A4: 3 | B4: R003 | C4: PAK | D4: 219.5 | F4: 11 | G4: 60 | H4: 0.019393333 | I4: 0.019486394 | J4: 0.019675654 | K4: 0.019809047 | L4: 0.019813005 | M4: 0.01972059 | N4: 0.019588872 | O4: 0.019631823 | P4: 0.019673238 | Q4: 0.01970031 | R4: 0.019592089 | S4: 0.019420925 | T4: 0.019270848 | U4: 0.01921931 | V4: 0.019214417 | W4: 0.019200147 | X4: 0.019239409 | Y4: 0.01927189 | Z4: 0.01932899 | AA4: 0.019431862 | AB4: 0.019509556 | AC4: 0.019647029 | AD4: 0.019711347 | AE4: 0.019815849 | AF4: 0.019882767 | AG4: 0.019954565 | AH4: 0.020024294 | AI4: 0.02008921 | AJ4: 0.020172545 | AK4: 0.020210533 | AL4: 0.020290845 | AM4: 0.02035729 | AN4: 0.020433401 | AO4: 0.02050686 | AP4: 0.020577678 | AQ4: 0.020665093 | AR4: 0.020719875 | AS4: 0.02078613 | AT4: 0.020823115 | AU4: 0.020851416 | AV4: 0.020869581 | AW4: 0.020907334 | AX4: 0.020949238 | AY4: 0.020973115 | AZ4: 0.021039926 | BA4: 0.021128065 | BB4: 0.021223976 | BC4: 0.021335589 | BD4: 0.021462672 | BE4: 0.021603305 | BF4: 0.021740246 | BG4: 0.021873307 | BH4: 0.022011395 | BI4: 0.022127115 | BJ4: 0.022234032 | BK4: 0.022326811 | BL4: 0.022408239 | BM4: 0.022498566 | BN4: 0.022575183 | BO4: 0.022636399 | BP4: 0.022649518 | BQ4: 0.022647015 | BR4: 0.02267686 | BS4: 0.022742939 | BT4: 0.022798205 | BU4: 0.022805532 | BV4: 0.022817021 | BW4: 0.022807384 | BX4: 0.022807442 | BY4: 0.022802041 | BZ4: 0.022807467 | CA4: 0.022810559 | CB4: 0.022807475 | CC4: 0.022805572 | CD4: 0.022783641 | CE4: 0.022777501 | CF4: 0.022761019 | CG4: 0.022743368 | CH4: 0.022718984 | CI4: 0.022688993 | CJ4: 0.022670961 | CK4: 0.022634577 | CL4: 0.022622013 | CM4: 0.022592681 | CN4: 0.022570293 | CO4: 0.022543684 | CP4: 0.022528914 | CQ4: 0.022518284 | CR4: 0.022491921 | CS4: 0.022472822 | CT4: 0.022459828 | CU4: 0.022431515 | CV4: 0.022405826 | CW4: 0.022373966 | CX4: 0.022336395 | CY4: 0.02228784 | CZ4: 0.022249896 | DA4: 0.02217867 | DB4: 0.022121694 | DC4: 0.022057982 | DD4: 0.021991878 | DE4: 0.02192456 | DF4: 0.021871556 | DG4: 0.021811545 | DH4: 0.021766332 | DI4: 0.021687582 | DJ4: 0.02163498 | DK4: 0.021568162 | DL4: 0.021508969 | DM4: 0.021471614 | DN4: 0.021412323 | DO4: 0.021385309 | DP4: 0.021341056 | DQ4: 0.021311913 | DR4: 0.021277414 | DS4: 0.021244167 | DT4: 0.021227573 | DU4: 0.02120265 | DV4: 0.021210446 | DW4: 0.021167805 | DX4: 0.021175519 | DY4: 0.021152894 | DZ4: 0.021162935 | EA4: 0.02116785 | EB4: 0.021163329 | EC4: 0.021176296 | ED4: 0.021155641 | EE4: 0.021154383 | EF4: 0.021089843 | EG4: 0.021079621 | EH4: 0.021049366 | EI4: 0.021042783 | EJ4: 0.021042663 | EK4: 0.021019183 | EL4: 0.021050905 | EM4: 0.021039713 | EN4: 0.021092083 | EO4: 0.021109958 | EP4: 0.021154713 | EQ4: 0.02119431 | ER4: 0.021196225 | ES4: 0.021229109 | ET4: 0.021178003 | EU4: 0.021161219 | EV4: 0.021110613 | EW4: 0.021059818 | EX4: 0.021027883 | EY4: 0.02098918 | EZ4: 0.020987754 | FA4: 0.020922242 | FB4: 0.020899302 | FC4: 0.020841476 | FD4: 0.020797625 | FE4: 0.020741025 | FF4: 0.020679701 | FG4: 0.020625838 | FH4: 0.020507866 | FI4: 0.020451685 | FJ4: 0.020369458 | FK4: 0.020306702 | FL4: 0.020210407 | FM4: 0.020091025 | FN4: 0.019975557 | FO4: 0.019812418 | FP4: 0.019684323 | FQ4: 0.019488036 | FR4: 0.019299839 | FS4: 0.019090495 | FT4: 0.018975625 | FU4: 0.018882222 | FV4: 0.018792444 | FW4: 0.018742019 | FX4: 0.018640985 | FY4: 0.018603227 | FZ4: 0.0185522 | GA4: 0.018517096 | GB4: 0.01849061 | GC4: 0.01845504 | GD4: 0.018441334 | GE4: 0.018413816 | GF4: 0.018384763 | GG4: 0.018319564 | GH4: 0.018299474 | GI4: 0.018273076 | GJ4: 0.018227247 | GK4: 0.018209446 | GL4: 0.018176653 | GM4: 0.018185754 | GN4: 0.018198139 | GO4: 0.018203702 | GP4: 0.018187501 | GQ4: 0.018182688 | GR4: 0.018208806 | GS4: 0.018205958 | GT4: 0.018246913 | GU4: 0.018228599 | GV4: 0.018246148 | GW4: 0.018225737 | GX4: 0.01824865 | GY4: 0.018283143 | GZ4: 0.018279231 | HA4: 0.018310253 | HB4: 0.01831369 | HC4: 0.018334165 | HD4: 0.018321746 | HE4: 0.018347428 | HF4: 0.018370643 | HG4: 0.018316394 | HH4: 0.018266263 | HI4: 0.018234126 | HJ4: 0.018200764 | HK4: 0.018081569 | HL4: 0.018014862 | HM4: 0.017906918 | HN4: 0.017760115 | HO4: 0.017656441 | HP4: 0.017519197 | HQ4: 0.017408839 | HR4: 0.017324079 | HS4: 0.017272145 | HT4: 0.017169407 | HU4: 0.017078032 | HV4: 0.017019413 | HW4: 0.016959216 | HX4: 0.016901553 | HY4: 0.016783606 | HZ4: 0.016794767 | IA4: 0.016795084 | IB4: 0.016713996 | IC4: 0.016628107 | ID4: 0.016651139 | IE4: 0.016604033 | IF4: 0.016326653 | IG4: 0.016279741 | IH4: 0.016204738 | II4: 0.016134332 | IJ4: 0.016066939 | IK4: 0.0159663 | IL4: 0.015873697 | IM4: 0.015736419 | IN4: 0.015640292 | IO4: 0.015574138 | IP4: 0.015442472 | IQ4: 0.015318836 | IR4: 0.015222939 | IS4: 0.015111282 | IT4: 0.014991675 | IU4: 0.014853421 | IV4: 0.014646807 | IW4: 0.014502042 | IX4: 0.014336907 | IY4: 0.014190062 | IZ4: 0.014023059 | JA4: 0.013864049 | JB4: 0.013648362 | JC4: 0.013399349 | JD4: 0.013270578 | JE4: 0.013141514 | JF4: 0.013046384 | JG4: 0.012995742 | JH4: 0.012951052 | JI4: 0.012930204 | JJ4: 0.012924255 | JK4: 0.012896539 | JL4: 0.012839322 | JM4: 0.012715994 | JN4: 0.012501354 | JO4: 0.012270567 | JP4: 0.012089765 | JQ4: 0.011790615 | JR4: 0.011515226 | JS4: 0.011249256 | JT4: 0.010987933 | JU4: 0.010730662 | JV4: 0.010429088 | JW4: 0.010055146 | JX4: 0.0096770594 | JY4: 0.0092766634 | JZ4: 0.0089130117 | KA4: 0.0086281 | KB4: 0.0083991636 | KC4: 0.0081720299 | KD4: 0.0079983238 | KE4: 0.0079736448 | KF4: 0.0079606687 | KG4: 0.007972075 | KH4: 0.0080379655 | KI4: 0.0081766533 | KJ4: 0.0083822235 | KK4: 0.0087376796 | KL4: 0.0093724102 | KM4: 0.010095563 | KN4: 0.011273181 | KO4: 0.012390581 | KP4: 0.013756719 | KQ4: 0.015296694 | KR4: 0.016943959 | KS4: 0.018711967 | KT4: 0.020267308 | KU4: 0.021586618 | KV4: 0.022782016
A5: 4 | B5: R004 | C5: PAK | D5: 185 | E5: 359.375 | F5: 10 | G5: 32 | H5: 0.017419107 | I5: 0.017459148 | J5: 0.017659961 | K5: 0.017835801 | L5: 0.017870673 | M5: 0.017836217 | N5: 0.01781996 | O5: 0.017885314 | P5: 0.017987225 | Q5: 0.0180194 | R5: 0.017931668 | S5: 0.017713115 | T5: 0.017528051 | U5: 0.017444778 | V5: 0.017414304 | W5: 0.017400054 | X5: 0.017409258 | Y5: 0.017434086 | Z5: 0.017473339 | AA5: 0.017536861 | AB5: 0.01757992 | AC5: 0.017676985 | AD5: 0.01772799 | AE5: 0.017800249 | AF5: 0.017838034 | AG5: 0.017888069 | AH5: 0.017929741 | AI5: 0.017961635 | AJ5: 0.018025774 | AK5: 0.018053331 | AL5: 0.018101725 | AM5: 0.018123913 | AN5: 0.018163436 | AO5: 0.01820955 | AP5: 0.018260837 | AQ5: 0.018316292 | AR5: 0.018306835 | AS5: 0.018342635 | AT5: 0.018330025 | AU5: 0.018337381 | AV5: 0.018337392 | AW5: 0.018330637 | AX5: 0.018339961 | AY5: 0.018339149 | AZ5: 0.018389416 | BA5: 0.018430356 | BB5: 0.018519841 | BC5: 0.018620418 | BD5: 0.01874087 | BE5: 0.018869903 | BF5: 0.019003273 | BG5: 0.019138077 | BH5: 0.019252408 | BI5: 0.019361075 | BJ5: 0.019458903 | BK5: 0.019538542 | BL5: 0.019611875 | BM5: 0.019682888 | BN5: 0.019741246 | BO5: 0.019795847 | BP5: 0.01980111 | BQ5: 0.019792699 | BR5: 0.019823583 | BS5: 0.019872555 | BT5: 0.019908276 | BU5: 0.019914511 | BV5: 0.019912722 | BW5: 0.019899569 | BX5: 0.019893675 | BY5: 0.019883163 | BZ5: 0.019871092 | CA5: 0.019869055 | CB5: 0.019858642 | CC5: 0.01985626 | CD5: 0.019839897 | CE5: 0.01981411 | CF5: 0.019799208 | CG5: 0.019784045 | CH5: 0.019751155 | CI5: 0.019720854 | CJ5: 0.019695159 | CK5: 0.019669215 | CL5: 0.019656916 | CM5: 0.019630959 | CN5: 0.019604761 | CO5: 0.019592709 | CP5: 0.019589386 | CQ5: 0.019587506 | CR5: 0.019591611 | CS5: 0.019569329 | CT5: 0.01955758 | CU5: 0.019532778 | CV5: 0.019506898 | CW5: 0.019476875 | CX5: 0.019437032 | CY5: 0.019396385 | CZ5: 0.01933634 | DA5: 0.019282544 | DB5: 0.019202564 | DC5: 0.019137401 | DD5: 0.019074312 | DE5: 0.019006624 | DF5: 0.018959737 | DG5: 0.018889684 | DH5: 0.018841663 | DI5: 0.018775047 | DJ5: 0.01872736 | DK5: 0.018670478 | DL5: 0.018595379 | DM5: 0.018544819 | DN5: 0.018492648 | DO5: 0.018474208 | DP5: 0.018418881 | DQ5: 0.018392163 | DR5: 0.018357893 | DS5: 0.018339157 | DT5: 0.018322037 | DU5: 0.018293158 | DV5: 0.018293785 | DW5: 0.018265318 | DX5: 0.018284511 | DY5: 0.018263517 | DZ5: 0.018261122 | EA5: 0.018254504 | EB5: 0.018254553 | EC5: 0.018265272 | ED5: 0.018235613 | EE5: 0.018245853 | EF5: 0.018205308 | EG5: 0.01820006 | EH5: 0.018172901 | EI5: 0.018166492 | EJ5: 0.018181127 | EK5: 0.018156208 | EL5: 0.018183789 | EM5: 0.01816319 | EN5: 0.018212067 | EO5: 0.018234594 | EP5: 0.018270194 | EQ5: 0.018309389 | ER5: 0.018311757 | ES5: 0.018334876 | ET5: 0.018309838 | EU5: 0.018313431 | EV5: 0.018256643 | EW5: 0.018193733 | EX5: 0.018144956 | EY5: 0.018127914 | EZ5: 0.018132842 | FA5: 0.018076657 | FB5: 0.018064036 | FC5: 0.017998117 | FD5: 0.017970773 | FE5: 0.017923507 | FF5: 0.017840283 | FG5: 0.017782501 | FH5: 0.017703848 | FI5: 0.017660435 | FJ5: 0.017574006 | FK5: 0.017523314 | FL5: 0.017435312 | FM5: 0.01733739 | FN5: 0.017249322 | FO5: 0.017068841 | FP5: 0.016951071 | FQ5: 0.016750304 | FR5: 0.016598914 | FS5: 0.016440722 | FT5: 0.016316248 | FU5: 0.016215609 | FV5: 0.016134882 | FW5: 0.016094836 | FX5: 0.016033206 | FY5: 0.016003448 | FZ5: 0.015958911 | GA5: 0.015932137 | GB5: 0.015900197 | GC5: 0.015868493 | GD5: 0.015876144 | GE5: 0.015793786 | GF5: 0.015792085 | GG5: 0.015756363 | GH5: 0.015735385 | GI5: 0.015715284 | GJ5: 0.015718772 | GK5: 0.015728952 | GL5: 0.015708143 | GM5: 0.015722812 | GN5: 0.01570004 | GO5: 0.015696945 | GP5: 0.015701965 | GQ5: 0.015704161 | GR5: 0.015733387 | GS5: 0.015728238 | GT5: 0.015767405 | GU5: 0.015785421 | GV5: 0.01582576 | GW5: 0.015849448 | GX5: 0.015840283 | GY5: 0.015852819 | GZ5: 0.01584917 | HA5: 0.015889199 | HB5: 0.015896784 | HC5: 0.015930885 | HD5: 0.015956579 | HE5: 0.015939789 | HF5: 0.015932629 | HG5: 0.015893552 | HH5: 0.015871614 | HI5: 0.01582159 | HJ5: 0.01582444 | HK5: 0.015795378 | HL5: 0.015808948 | HM5: 0.015678222 | HN5: 0.015459584 | HO5: 0.015355062 | HP5: 0.015279689 | HQ5: 0.015180745 | HR5: 0.015078114 | HS5: 0.015031888 | HT5: 0.014980682 | HU5: 0.014900888 | HV5: 0.01485345 | HW5: 0.01483422 | HX5: 0.014795407 | HY5: 0.01473251 | HZ5: 0.014726558 | IA5: 0.014738124 | IB5: 0.014678591 | IC5: 0.01462 | ID5: 0.014566268 | IE5: 0.014504145 | IF5: 0.014325647 | IG5: 0.014293122 | IH5: 0.014215992 | II5: 0.014130128 | IJ5: 0.014043704 | IK5: 0.01395667 | IL5: 0.013868397 | IM5: 0.013798711 | IN5: 0.013671272 | IO5: 0.013525288 | IP5: 0.013459851 | IQ5: 0.013401014 | IR5: 0.013279142 | IS5: 0.013148877 | IT5: 0.013016567 | IU5: 0.012892686 | IV5: 0.012790977 | IW5: 0.012686766 | IX5: 0.012574479 | IY5: 0.012400256 | IZ5: 0.012236397 | JA5: 0.012040987 | JB5: 0.01180735 | JC5: 0.011630502 | JD5: 0.011504587 | JE5: 0.011388336 | JF5: 0.011280996 | JG5: 0.011207438 | JH5: 0.011145959 | JI5: 0.011160975 | JJ5: 0.011162249 | JK5: 0.011172068 | JL5: 0.011199737 | JM5: 0.01114684 | JN5: 0.010990968 | JO5: 0.010828416 | JP5: 0.010681225 | JQ5: 0.010520538 | JR5: 0.010298228 | JS5: 0.010052404 | JT5: 0.0097804265 | JU5: 0.0094900989 | JV5: 0.0090851286 | JW5: 0.0086935468 | JX5: 0.0084292237 | JY5: 0.0080701602 | JZ5: 0.007720499 | KA5: 0.0074786936 | KB5: 0.0073001191 | KC5: 0.0071554585 | KD5: 0.0070304724 | KE5: 0.006914089 | KF5: 0.006860026 | KG5: 0.006936548 | KH5: 0.0070200342 | KI5: 0.0072165856 | KJ5: 0.0074395774 | KK5: 0.0078023654 | KL5: 0.0084251986 | KM5: 0.0091375461 | KN5: 0.010319075 | KO5: 0.011507402 | KP5: 0.012906776 | KQ5: 0.014601108 | KR5: 0.01642353 | KS5: 0.017848428 | KT5: 0.019250896 | KU5: 0.020795489 | KV5: 0.022009914
A6: 5 | B6: R005 | C6: PAK | D6: 225 | E6: 285.71429 | F6: 11 | G6: 44 | H6: 0.020592248 | I6: 0.020737946 | J6: 0.021036027 | K6: 0.021263236 | L6: 0.021273391 | M6: 0.021191978 | N6: 0.021046691 | O6: 0.021119998 | P6: 0.021260496 | Q6: 0.02130674 | R6: 0.021221902 | S6: 0.021036453 | T6: 0.020902164 | U6: 0.020772891 | V6: 0.020800369 | W6: 0.020835274 | X6: 0.020885757 | Y6: 0.020936119 | Z6: 0.021010804 | AA6: 0.021128415 | AB6: 0.021261584 | AC6: 0.021410664 | AD6: 0.021498639 | AE6: 0.021620823 | AF6: 0.021709689 | AG6: 0.021790207 | AH6: 0.021859168 | AI6: 0.021949701 | AJ6: 0.022043972 | AK6: 0.022105349 | AL6: 0.022204893 | AM6: 0.022292604 | AN6: 0.022386646 | AO6: 0.022485717 | AP6: 0.02257988 | AQ6: 0.022673411 | AR6: 0.022756794 | AS6: 0.022847577 | AT6: 0.022894229 | AU6: 0.022937432 | AV6: 0.022974147 | AW6: 0.023016306 | AX6: 0.023065878 | AY6: 0.023130949 | AZ6: 0.023222543 | BA6: 0.023341302 | BB6: 0.023475862 | BC6: 0.023625488 | BD6: 0.023797058 | BE6: 0.023969312 | BF6: 0.024171746 | BG6: 0.024353439 | BH6: 0.024518136 | BI6: 0.024671646 | BJ6: 0.024812663 | BK6: 0.024940744 | BL6: 0.025061342 | BM6: 0.025190131 | BN6: 0.02528833 | BO6: 0.025387036 | BP6: 0.02541646 | BQ6: 0.02544436 | BR6: 0.02549449 | BS6: 0.025566655 | BT6: 0.025638408 | BU6: 0.025661337 | BV6: 0.02568069 | BW6: 0.025678884 | BX6: 0.025692701 | BY6: 0.025704463 | BZ6: 0.025717831 | CA6: 0.025716789 | CB6: 0.025712539 | CC6: 0.025712744 | CD6: 0.025685532 | CE6: 0.025683472 | CF6: 0.025654608 | CG6: 0.025636583 | CH6: 0.025612226 | CI6: 0.025578322 | CJ6: 0.025552995 | CK6: 0.025521148 | CL6: 0.025510934 | CM6: 0.025473486 | CN6: 0.025443316 | CO6: 0.025426246 | CP6: 0.025407565 | CQ6: 0.025399674 | CR6: 0.025378912 | CS6: 0.025379845 | CT6: 0.02535853 | CU6: 0.025344363 | CV6: 0.025312253 | CW6: 0.025274301 | CX6: 0.025236091 | CY6: 0.025182592 | CZ6: 0.02511666 | DA6: 0.025039264 | DB6: 0.024979169 | DC6: 0.024895631 | DD6: 0.024814663 | DE6: 0.024729971 | DF6: 0.024658899 | DG6: 0.024587174 | DH6: 0.024517926 | DI6: 0.02444118 | DJ6: 0.02437056 | DK6: 0.024285026 | DL6: 0.024212279 | DM6: 0.024147124 | DN6: 0.024087454 | DO6: 0.024042954 | DP6: 0.023992083 | DQ6: 0.023953855 | DR6: 0.023888653 | DS6: 0.023866578 | DT6: 0.023851653 | DU6: 0.023823798 | DV6: 0.023827604 | DW6: 0.023789933 | DX6: 0.023801255 | DY6: 0.023779904 | DZ6: 0.023774614 | EA6: 0.023760704 | EB6: 0.023765037 | EC6: 0.023772903 | ED6: 0.023728613 | EE6: 0.023723416 | EF6: 0.023688049 | EG6: 0.023672832 | EH6: 0.023648424 | EI6: 0.023629998 | EJ6: 0.023621331 | EK6: 0.023586111 | EL6: 0.023616909 | EM6: 0.023604965 | EN6: 0.023655683 | EO6: 0.023674601 | EP6: 0.023728798 | EQ6: 0.023777122 | ER6: 0.023782288 | ES6: 0.023811818 | ET6: 0.023759672 | EU6: 0.023738176 | EV6: 0.023684858 | EW6: 0.023630912 | EX6: 0.023581533 | EY6: 0.02355272 | EZ6: 0.023550115 | FA6: 0.023451936 | FB6: 0.023419129 | FC6: 0.023323165 | FD6: 0.0232699 | FE6: 0.023199817 | FF6: 0.02312248 | FG6: 0.023054747 | FH6: 0.022973442 | FI6: 0.022910103 | FJ6: 0.022796168 | FK6: 0.022720774 | FL6: 0.022605672 | FM6: 0.022470998 | FN6: 0.022338271 | FO6: 0.022151587 | FP6: 0.021987943 | FQ6: 0.021766714 | FR6: 0.02156729 | FS6: 0.021356459 | FT6: 0.021199818 | FU6: 0.021085811 | FV6: 0.020979882 | FW6: 0.020922967 | FX6: 0.02084245 | FY6: 0.020796712 | FZ6: 0.020725765 | GA6: 0.020696435 | GB6: 0.020663161 | GC6: 0.020609086 | GD6: 0.020593554 | GE6: 0.020538883 | GF6: 0.020540889 | GG6: 0.020476064 | GH6: 0.020440669 | GI6: 0.020398171 | GJ6: 0.020353038 | GK6: 0.020332563 | GL6: 0.020348101 | GM6: 0.020362769 | GN6: 0.020360408 | GO6: 0.020338352 | GP6: 0.020336363 | GQ6: 0.020333454 | GR6: 0.020361792 | GS6: 0.020324713 | GT6: 0.020311787 | GU6: 0.020299203 | GV6: 0.020313606 | GW6: 0.020304297 | GX6: 0.020333273 | GY6: 0.020360509 | GZ6: 0.020348953 | HA6: 0.0203773 | HB6: 0.020387792 | HC6: 0.020401751 | HD6: 0.020420004 | HE6: 0.020386165 | HF6: 0.020380881 | HG6: 0.020331982 | HH6: 0.020309684 | HI6: 0.020238809 | HJ6: 0.020217611 | HK6: 0.020146292 | HL6: 0.020065264 | HM6: 0.019900694 | HN6: 0.019692646 | HO6: 0.019552771 | HP6: 0.019420176 | HQ6: 0.019276963 | HR6: 0.019067543 | HS6: 0.019000072 | HT6: 0.018921656 | HU6: 0.01886168 | HV6: 0.018795235 | HW6: 0.018707594 | HX6: 0.018674294 | HY6: 0.018544815 | HZ6: 0.018526561 | IA6: 0.018504938 | IB6: 0.018401854 | IC6: 0.018311332 | ID6: 0.018232355 | IE6: 0.018139289 | IF6: 0.018107171 | IG6: 0.018026567 | IH6: 0.017833786 | II6: 0.017753772 | IJ6: 0.017664245 | IK6: 0.017537255 | IL6: 0.017424011 | IM6: 0.017342025 | IN6: 0.017185462 | IO6: 0.017089071 | IP6: 0.017025755 | IQ6: 0.01697056 | IR6: 0.016818594 | IS6: 0.016665415 | IT6: 0.016503109 | IU6: 0.016364377 | IV6: 0.016209821 | IW6: 0.016083718 | IX6: 0.015946626 | IY6: 0.015734471 | IZ6: 0.015548853 | JA6: 0.01540569 | JB6: 0.015168815 | JC6: 0.014969223 | JD6: 0.014847112 | JE6: 0.01472717 | JF6: 0.014599671 | JG6: 0.014508751 | JH6: 0.01442759 | JI6: 0.014399946 | JJ6: 0.014300444 | JK6: 0.014204996 | JL6: 0.014049825 | JM6: 0.013905719 | JN6: 0.013678363 | JO6: 0.013416972 | JP6: 0.013155073 | JQ6: 0.012817966 | JR6: 0.012482925 | JS6: 0.012218671 | JT6: 0.011831601 | JU6: 0.011410791 | JV6: 0.010988664 | JW6: 0.010541152 | JX6: 0.010107316 | JY6: 0.0096434393 | JZ6: 0.0093130387 | KA6: 0.0090204383 | KB6: 0.0088189099 | KC6: 0.0086362039 | KD6: 0.0085000846 | KE6: 0.0083997289 | KF6: 0.0083479302 | KG6: 0.0082801533 | KH6: 0.0083074685 | KI6: 0.008369118 | KJ6: 0.0086111433 | KK6: 0.009008713 | KL6: 0.0096181353 | KM6: 0.0103085 | KN6: 0.011447971 | KO6: 0.012672266 | KP6: 0.014288247 | KQ6: 0.015684775 | KR6: 0.017045421 | KS6: 0.018937904 | KT6: 0.020569957 | KU6: 0.022047058 | KV6: 0.02321055
A7: 6 | B7: R006 | C7: PAK | D7: 215.5 | F7: 8.9 | G7: 58 | H7: 0.021990277 | I7: 0.022231169 | J7: 0.022577475 | K7: 0.022804357 | L7: 0.022794188 | M7: 0.022649438 | N7: 0.022533191 | O7: 0.02259801 | P7: 0.022681702 | Q7: 0.022677958 | R7: 0.022513639 | S7: 0.022338451 | T7: 0.022203413 | U7: 0.022071718 | V7: 0.022064657 | W7: 0.022076746 | X7: 0.022138021 | Y7: 0.022196502 | Z7: 0.022269655 | AA7: 0.022370232 | AB7: 0.022450363 | AC7: 0.022567712 | AD7: 0.02263366 | AE7: 0.022738097 | AF7: 0.022800501 | AG7: 0.022862732 | AH7: 0.02292473 | AI7: 0.022983948 | AJ7: 0.023050076 | AK7: 0.023102805 | AL7: 0.023165932 | AM7: 0.023212308 | AN7: 0.023273272 | AO7: 0.023335138 | AP7: 0.023380726 | AQ7: 0.02344451 | AR7: 0.023483194 | AS7: 0.023543964 | AT7: 0.023566889 | AU7: 0.023584405 | AV7: 0.023599526 | AW7: 0.023627128 | AX7: 0.02365328 | AY7: 0.023672777 | AZ7: 0.023729626 | BA7: 0.023793959 | BB7: 0.023881555 | BC7: 0.023973541 | BD7: 0.024083341 | BE7: 0.024187539 | BF7: 0.024292794 | BG7: 0.024399509 | BH7: 0.024515985 | BI7: 0.024605277 | BJ7: 0.024681192 | BK7: 0.024741989 | BL7: 0.024793579 | BM7: 0.024858813 | BN7: 0.024907099 | BO7: 0.024946057 | BP7: 0.024927757 | BQ7: 0.024893171 | BR7: 0.024904961 | BS7: 0.024940273 | BT7: 0.024970757 | BU7: 0.024963225 | BV7: 0.024948365 | BW7: 0.024920942 | BX7: 0.024919002 | BY7: 0.024900035 | BZ7: 0.024874325 | CA7: 0.024846568 | CB7: 0.024824172 | CC7: 0.024797272 | CD7: 0.024761996 | CE7: 0.024731909 | CF7: 0.024686991 | CG7: 0.024645094 | CH7: 0.024605425 | CI7: 0.024555966 | CJ7: 0.024520529 | CK7: 0.024471301 | CL7: 0.024444762 | CM7: 0.024408568 | CN7: 0.024381846 | CO7: 0.024362111 | CP7: 0.024342735 | CQ7: 0.024335453 | CR7: 0.024315556 | CS7: 0.024299127 | CT7: 0.024274637 | CU7: 0.02424704 | CV7: 0.024214629 | CW7: 0.024168966 | CX7: 0.024127398 | CY7: 0.024056344 | CZ7: 0.023997051 | DA7: 0.023902987 | DB7: 0.023807142 | DC7: 0.02371806 | DD7: 0.023619466 | DE7: 0.023537279 | DF7: 0.023457193 | DG7: 0.023363853 | DH7: 0.023289113 | DI7: 0.023212761 | DJ7: 0.023124985 | DK7: 0.023028692 | DL7: 0.022940205 | DM7: 0.022861542 | DN7: 0.022784937 | DO7: 0.022744947 | DP7: 0.022671629 | DQ7: 0.022619745 | DR7: 0.022562438 | DS7: 0.022534374 | DT7: 0.022511973 | DU7: 0.022480796 | DV7: 0.022478936 | DW7: 0.022434045 | DX7: 0.022445025 | DY7: 0.022426997 | DZ7: 0.022444005 | EA7: 0.022454597 | EB7: 0.022463238 | EC7: 0.022483328 | ED7: 0.022456533 | EE7: 0.022468073 | EF7: 0.022432683 | EG7: 0.022431339 | EH7: 0.022412232 | EI7: 0.022397906 | EJ7: 0.022402888 | EK7: 0.022369447 | EL7: 0.022386659 | EM7: 0.022359759 | EN7: 0.022395492 | EO7: 0.022419885 | EP7: 0.022433242 | EQ7: 0.022451689 | ER7: 0.022433208 | ES7: 0.022438876 | ET7: 0.022366478 | EU7: 0.022341905 | EV7: 0.022292741 | EW7: 0.022232003 | EX7: 0.022180854 | EY7: 0.022147939 | EZ7: 0.022141995 | FA7: 0.022084291 | FB7: 0.022042176 | FC7: 0.021970874 | FD7: 0.02191181 | FE7: 0.021835389 | FF7: 0.021768306 | FG7: 0.02169727 | FH7: 0.021588916 | FI7: 0.021527885 | FJ7: 0.021420439 | FK7: 0.021331817 | FL7: 0.021208519 | FM7: 0.021093757 | FN7: 0.020975288 | FO7: 0.020775616 | FP7: 0.020620649 | FQ7: 0.020404109 | FR7: 0.020229613 | FS7: 0.020057351 | FT7: 0.019899148 | FU7: 0.019777914 | FV7: 0.019685257 | FW7: 0.01963502 | FX7: 0.019562015 | FY7: 0.019525484 | FZ7: 0.019491133 | GA7: 0.019458753 | GB7: 0.019430058 | GC7: 0.019386601 | GD7: 0.019373925 | GE7: 0.019283804 | GF7: 0.019263114 | GG7: 0.019201367 | GH7: 0.019185527 | GI7: 0.019152794 | GJ7: 0.019143811 | GK7: 0.019148307 | GL7: 0.019132851 | GM7: 0.019140062 | GN7: 0.019095088 | GO7: 0.019084632 | GP7: 0.019069721 | GQ7: 0.019073537 | GR7: 0.019105787 | GS7: 0.019072035 | GT7: 0.019090953 | GU7: 0.019116078 | GV7: 0.019141096 | GW7: 0.019137466 | GX7: 0.019165167 | GY7: 0.019207173 | GZ7: 0.019186667 | HA7: 0.019211173 | HB7: 0.019217273 | HC7: 0.019236188 | HD7: 0.019229341 | HE7: 0.01919021 | HF7: 0.019148733 | HG7: 0.019120882 | HH7: 0.019099569 | HI7: 0.019072955 | HJ7: 0.019064727 | HK7: 0.018992387 | HL7: 0.018974549 | HM7: 0.018835901 | HN7: 0.018639155 | HO7: 0.018523768 | HP7: 0.018318656 | HQ7: 0.018173045 | HR7: 0.018038933 | HS7: 0.017953863 | HT7: 0.017854615 | HU7: 0.017805286 | HV7: 0.017767157 | HW7: 0.017706961 | HX7: 0.017666106 | HY7: 0.017645295 | HZ7: 0.017608151 | IA7: 0.017556271 | IB7: 0.017513142 | IC7: 0.01747 | ID7: 0.017378266 | IE7: 0.017303415 | IF7: 0.017227575 | IG7: 0.017175192 | IH7: 0.017107476 | II7: 0.016995333 | IJ7: 0.01686493 | IK7: 0.016719891 | IL7: 0.016593896 | IM7: 0.016471883 | IN7: 0.016361478 | IO7: 0.016361136 | IP7: 0.016244822 | IQ7: 0.016119783 | IR7: 0.015981311 | IS7: 0.015839299 | IT7: 0.015649991 | IU7: 0.015519754 | IV7: 0.01536967 | IW7: 0.015252885 | IX7: 0.015124379 | IY7: 0.014956792 | IZ7: 0.014777438 | JA7: 0.014599573 | JB7: 0.014359951 | JC7: 0.014153871 | JD7: 0.014017982 | JE7: 0.013865885 | JF7: 0.013794468 | JG7: 0.013766864 | JH7: 0.01370109 | JI7: 0.013704225 | JJ7: 0.013630046 | JK7: 0.013593012 | JL7: 0.013562636 | JM7: 0.013434195 | JN7: 0.013211362 | JO7: 0.01296789 | JP7: 0.012748678 | JQ7: 0.012438903 | JR7: 0.012133757 | JS7: 0.011829827 | JT7: 0.011539744 | JU7: 0.011231487 | JV7: 0.010830357 | JW7: 0.010424985 | JX7: 0.0099474084 | JY7: 0.0094795014 | JZ7: 0.0091385974 | KA7: 0.0088733589 | KB7: 0.00864776 | KC7: 0.0084560577 | KD7: 0.0083128812 | KE7: 0.00822005 | KF7: 0.0081833312 | KG7: 0.0081785375 | KH7: 0.0082850602 | KI7: 0.0085240243 | KJ7: 0.0087491036 | KK7: 0.0091150018 | KL7: 0.0097417136 | KM7: 0.010488194 | KN7: 0.011472331 | KO7: 0.012646478 | KP7: 0.014206136 | KQ7: 0.015738027 | KR7: 0.017362394 | KS7: 0.018997947 | KT7: 0.020512821 | KU7: 0.021849737 | KV7: 0.022988231
A8: 7 | B8: R007 | C8: PAK | D8: 222 | F8: 7.2 | G8: 54 | H8: 0.026896073 | I8: 0.027311384 | J8: 0.027801593 | K8: 0.028138334 | L8: 0.028160822 | M8: 0.027985667 | N8: 0.027828897 | O8: 0.02788693 | P8: 0.027975176 | Q8: 0.027945228 | R8: 0.027751463 | S8: 0.02752027 | T8: 0.027375969 | U8: 0.027316921 | V8: 0.027367118 | W8: 0.027489978 | X8: 0.027568918 | Y8: 0.027673397 | Z8: 0.027758213 | AA8: 0.02787775 | AB8: 0.028016697 | AC8: 0.028144493 | AD8: 0.028250111 | AE8: 0.028369926 | AF8: 0.028468998 | AG8: 0.028540339 | AH8: 0.028622224 | AI8: 0.028665493 | AJ8: 0.028724299 | AK8: 0.028779578 | AL8: 0.028837066 | AM8: 0.028873569 | AN8: 0.028926159 | AO8: 0.028989974 | AP8: 0.029046885 | AQ8: 0.029102191 | AR8: 0.029156872 | AS8: 0.029198337 | AT8: 0.029198825 | AU8: 0.029196816 | AV8: 0.029198877 | AW8: 0.029214155 | AX8: 0.029234978 | AY8: 0.029245064 | AZ8: 0.029287587 | BA8: 0.029358552 | BB8: 0.029438308 | BC8: 0.02952914 | BD8: 0.029634843 | BE8: 0.029745968 | BF8: 0.029867412 | BG8: 0.029968586 | BH8: 0.030067333 | BI8: 0.03014421 | BJ8: 0.030211526 | BK8: 0.03027465 | BL8: 0.03033279 | BM8: 0.030390003 | BN8: 0.030432321 | BO8: 0.030457731 | BP8: 0.03042909 | BQ8: 0.030396887 | BR8: 0.030391439 | BS8: 0.030418224 | BT8: 0.030442706 | BU8: 0.030423358 | BV8: 0.030389004 | BW8: 0.030345898 | BX8: 0.030327279 | BY8: 0.030284711 | BZ8: 0.030247535 | CA8: 0.030225186 | CB8: 0.030189231 | CC8: 0.030161783 | CD8: 0.030100131 | CE8: 0.030052414 | CF8: 0.029996967 | CG8: 0.029944471 | CH8: 0.029884191 | CI8: 0.029815128 | CJ8: 0.029753155 | CK8: 0.029681157 | CL8: 0.029636764 | CM8: 0.029572506 | CN8: 0.029509898 | CO8: 0.029457209 | CP8: 0.029413698 | CQ8: 0.029362467 | CR8: 0.029318015 | CS8: 0.029280065 | CT8: 0.029229764 | CU8: 0.029174651 | CV8: 0.029114271 | CW8: 0.029051804 | CX8: 0.028985662 | CY8: 0.028908058 | CZ8: 0.028824907 | DA8: 0.028711462 | DB8: 0.02862911 | DC8: 0.028516388 | DD8: 0.028398524 | DE8: 0.028295227 | DF8: 0.028185539 | DG8: 0.028099081 | DH8: 0.028001108 | DI8: 0.027913574 | DJ8: 0.027808183 | DK8: 0.027702114 | DL8: 0.027598361 | DM8: 0.02751269 | DN8: 0.027414763 | DO8: 0.027335774 | DP8: 0.027261835 | DQ8: 0.027194457 | DR8: 0.027121759 | DS8: 0.027065125 | DT8: 0.027014872 | DU8: 0.026965467 | DV8: 0.026927921 | DW8: 0.026888764 | DX8: 0.026857829 | DY8: 0.026807378 | DZ8: 0.026786819 | EA8: 0.026763271 | EB8: 0.026743279 | EC8: 0.026732651 | ED8: 0.026702806 | EE8: 0.026655365 | EF8: 0.026609904 | EG8: 0.026563676 | EH8: 0.0265219 | EI8: 0.026504954 | EJ8: 0.026491619 | EK8: 0.02644119 | EL8: 0.02644046 | EM8: 0.026376373 | EN8: 0.026388526 | EO8: 0.026376267 | EP8: 0.026379967 | EQ8: 0.026384807 | ER8: 0.026353376 | ES8: 0.026333224 | ET8: 0.026260822 | EU8: 0.026208814 | EV8: 0.026121223 | EW8: 0.026046216 | EX8: 0.025974042 | EY8: 0.025900021 | EZ8: 0.025863231 | FA8: 0.025789634 | FB8: 0.025728236 | FC8: 0.025637578 | FD8: 0.025545785 | FE8: 0.025448008 | FF8: 0.025344387 | FG8: 0.025247493 | FH8: 0.025113773 | FI8: 0.025018519 | FJ8: 0.024883805 | FK8: 0.024765487 | FL8: 0.024617725 | FM8: 0.024478929 | FN8: 0.024331834 | FO8: 0.024117159 | FP8: 0.02392198 | FQ8: 0.023647051 | FR8: 0.02343366 | FS8: 0.023212055 | FT8: 0.023037253 | FU8: 0.022898968 | FV8: 0.022768653 | FW8: 0.022692098 | FX8: 0.022592868 | FY8: 0.022537315 | FZ8: 0.022466148 | GA8: 0.022419619 | GB8: 0.022356139 | GC8: 0.022293636 | GD8: 0.02226662 | GE8: 0.022208418 | GF8: 0.022191532 | GG8: 0.022132923 | GH8: 0.022093606 | GI8: 0.022052261 | GJ8: 0.02201713 | GK8: 0.021999146 | GL8: 0.021960936 | GM8: 0.021958056 | GN8: 0.021924331 | GO8: 0.021917199 | GP8: 0.021904256 | GQ8: 0.021883039 | GR8: 0.021887321 | GS8: 0.021888208 | GT8: 0.021889915 | GU8: 0.02191935 | GV8: 0.021931196 | GW8: 0.021929212 | GX8: 0.021932656 | GY8: 0.021959997 | GZ8: 0.021954434 | HA8: 0.021984224 | HB8: 0.021959654 | HC8: 0.021971067 | HD8: 0.021967746 | HE8: 0.021921704 | HF8: 0.021885993 | HG8: 0.021853782 | HH8: 0.021825521 | HI8: 0.021690483 | HJ8: 0.021654838 | HK8: 0.021621701 | HL8: 0.021531032 | HM8: 0.021375907 | HN8: 0.02115192 | HO8: 0.020957973 | HP8: 0.020743266 | HQ8: 0.020597725 | HR8: 0.020546287 | HS8: 0.020456926 | HT8: 0.020346433 | HU8: 0.020261266 | HV8: 0.020183167 | HW8: 0.020103416 | HX8: 0.020039718 | HY8: 0.01992299 | HZ8: 0.019874892 | IA8: 0.019760709 | IB8: 0.019715509 | IC8: 0.019663076 | ID8: 0.019577468 | IE8: 0.019501747 | IF8: 0.019304636 | IG8: 0.019243853 | IH8: 0.019188995 | II8: 0.019062928 | IJ8: 0.018924263 | IK8: 0.018783701 | IL8: 0.018643672 | IM8: 0.01855998 | IN8: 0.018432999 | IO8: 0.018336724 | IP8: 0.018177928 | IQ8: 0.017995445 | IR8: 0.017918871 | IS8: 0.01781035 | IT8: 0.01763914 | IU8: 0.017500937 | IV8: 0.017306161 | IW8: 0.017170974 | IX8: 0.017014303 | IY8: 0.016861992 | IZ8: 0.016687224 | JA8: 0.016461841 | JB8: 0.016205736 | JC8: 0.015994741 | JD8: 0.015839574 | JE8: 0.015703618 | JF8: 0.015570661 | JG8: 0.015480561 | JH8: 0.015430373 | JI8: 0.015404165 | JJ8: 0.015334898 | JK8: 0.015252693 | JL8: 0.015185482 | JM8: 0.014983819 | JN8: 0.014682939 | JO8: 0.014386105 | JP8: 0.0140986 | JQ8: 0.01386744 | JR8: 0.013515464 | JS8: 0.013128862 | JT8: 0.012762675 | JU8: 0.012351918 | JV8: 0.011851327 | JW8: 0.01135739 | JX8: 0.010886573 | JY8: 0.010402591 | JZ8: 0.01012068 | KA8: 0.0097716301 | KB8: 0.0094910285 | KC8: 0.0092617004 | KD8: 0.0091015221 | KE8: 0.0089413166 | KF8: 0.0088859146 | KG8: 0.0088333442 | KH8: 0.0089239955 | KI8: 0.0091383934 | KJ8: 0.0093386923 | KK8: 0.0096972718 | KL8: 0.010362494 | KM8: 0.011094203 | KN8: 0.012298495 | KO8: 0.013516065 | KP8: 0.015036483 | KQ8: 0.016648681 | KR8: 0.018326289 | KS8: 0.019983317 | KT8: 0.021418419 | KU8: 0.022818971 | KV8: 0.024087948
A9: 8 | B9: R008 | C9: PAK | D9: 204.5 | E9: 345.45455 | F9: 7 | G9: 56 | H9: 0.022508923 | I9: 0.02274292 | J9: 0.023100329 | K9: 0.02334664 | L9: 0.023347965 | M9: 0.02319507 | N9: 0.023072118 | O9: 0.023073385 | P9: 0.023100743 | Q9: 0.023078496 | R9: 0.022899527 | S9: 0.022647718 | T9: 0.022461853 | U9: 0.022388347 | V9: 0.022383801 | W9: 0.022377678 | X9: 0.02239121 | Y9: 0.022416225 | Z9: 0.022473026 | AA9: 0.022563534 | AB9: 0.02262733 | AC9: 0.02272474 | AD9: 0.022774764 | AE9: 0.022842089 | AF9: 0.022886952 | AG9: 0.022925965 | AH9: 0.022966843 | AI9: 0.023000624 | AJ9: 0.023041445 | AK9: 0.02304886 | AL9: 0.023085503 | AM9: 0.023114015 | AN9: 0.023151843 | AO9: 0.023186958 | AP9: 0.023208122 | AQ9: 0.023240843 | AR9: 0.023263043 | AS9: 0.023286484 | AT9: 0.023277674 | AU9: 0.023262364 | AV9: 0.023245962 | AW9: 0.02323939 | AX9: 0.023242128 | AY9: 0.023247371 | AZ9: 0.023268802 | BA9: 0.023273202 | BB9: 0.023335691 | BC9: 0.023405461 | BD9: 0.023469327 | BE9: 0.023534073 | BF9: 0.023612428 | BG9: 0.023690296 | BH9: 0.02374876 | BI9: 0.023791272 | BJ9: 0.023824189 | BK9: 0.023865406 | BL9: 0.023894665 | BM9: 0.023933604 | BN9: 0.023946046 | BO9: 0.023968267 | BP9: 0.023936415 | BQ9: 0.023907181 | BR9: 0.023893131 | BS9: 0.023910007 | BT9: 0.023932532 | BU9: 0.023909752 | BV9: 0.023871328 | BW9: 0.023833876 | BX9: 0.023810774 | BY9: 0.023778477 | BZ9: 0.02373745 | CA9: 0.023703626 | CB9: 0.023663643 | CC9: 0.023622206 | CD9: 0.023566987 | CE9: 0.023535639 | CF9: 0.023489565 | CG9: 0.023442472 | CH9: 0.023391478 | CI9: 0.023333372 | CJ9: 0.023289468 | CK9: 0.023234864 | CL9: 0.02318421 | CM9: 0.023132583 | CN9: 0.023086482 | CO9: 0.02303013 | CP9: 0.022987396 | CQ9: 0.022953053 | CR9: 0.022907131 | CS9: 0.022876126 | CT9: 0.022820266 | CU9: 0.022766917 | CV9: 0.022718045 | CW9: 0.022668401 | CX9: 0.022607342 | CY9: 0.022544331 | CZ9: 0.022482243 | DA9: 0.022400747 | DB9: 0.022330908 | DC9: 0.022248155 | DD9: 0.02216399 | DE9: 0.022085284 | DF9: 0.022010493 | DG9: 0.021916544 | DH9: 0.021859264 | DI9: 0.021799446 | DJ9: 0.021727329 | DK9: 0.021640796 | DL9: 0.021559431 | DM9: 0.021498533 | DN9: 0.02144175 | DO9: 0.021411152 | DP9: 0.021324242 | DQ9: 0.021283933 | DR9: 0.021237283 | DS9: 0.021195245 | DT9: 0.021156691 | DU9: 0.021107454 | DV9: 0.021095465 | DW9: 0.021047696 | DX9: 0.021050532 | DY9: 0.021016699 | DZ9: 0.021008557 | EA9: 0.020997912 | EB9: 0.020970073 | EC9: 0.020962466 | ED9: 0.020909877 | EE9: 0.020905379 | EF9: 0.020840435 | EG9: 0.020819762 | EH9: 0.020787964 | EI9: 0.020778602 | EJ9: 0.020784823 | EK9: 0.020757256 | EL9: 0.020768393 | EM9: 0.020745208 | EN9: 0.020771904 | EO9: 0.020768871 | EP9: 0.020774894 | EQ9: 0.020783317 | ER9: 0.02076312 | ES9: 0.02076066 | ET9: 0.020703696 | EU9: 0.020675106 | EV9: 0.020594182 | EW9: 0.020531727 | EX9: 0.02047859 | EY9: 0.020418851 | EZ9: 0.020408889 | FA9: 0.020352009 | FB9: 0.020298737 | FC9: 0.020200106 | FD9: 0.020145164 | FE9: 0.020077781 | FF9: 0.020008543 | FG9: 0.019935582 | FH9: 0.019824119 | FI9: 0.019761689 | FJ9: 0.019662937 | FK9: 0.019572155 | FL9: 0.01945853 | FM9: 0.019332009 | FN9: 0.019218145 | FO9: 0.0190304 | FP9: 0.018882375 | FQ9: 0.018675081 | FR9: 0.018511972 | FS9: 0.018339912 | FT9: 0.018194455 | FU9: 0.018099387 | FV9: 0.017997224 | FW9: 0.017952889 | FX9: 0.01786513 | FY9: 0.017831939 | FZ9: 0.017778344 | GA9: 0.017757029 | GB9: 0.017722479 | GC9: 0.017685922 | GD9: 0.017680644 | GE9: 0.017607268 | GF9: 0.017587736 | GG9: 0.017536207 | GH9: 0.017533736 | GI9: 0.017534417 | GJ9: 0.017491956 | GK9: 0.017482285 | GL9: 0.017472087 | GM9: 0.017474384 | GN9: 0.017431765 | GO9: 0.0174452 | GP9: 0.01744627 | GQ9: 0.017430312 | GR9: 0.017429661 | GS9: 0.017426514 | GT9: 0.017453731 | GU9: 0.017463927 | GV9: 0.017488057 | GW9: 0.017485243 | GX9: 0.017498881 | GY9: 0.017527227 | GZ9: 0.017542508 | HA9: 0.017588025 | HB9: 0.017570555 | HC9: 0.017600179 | HD9: 0.017596336 | HE9: 0.017590695 | HF9: 0.017588506 | HG9: 0.017540879 | HH9: 0.017512125 | HI9: 0.017455694 | HJ9: 0.017427492 | HK9: 0.017343127 | HL9: 0.017296921 | HM9: 0.017170293 | HN9: 0.017024592 | HO9: 0.016917192 | HP9: 0.016734683 | HQ9: 0.016622744 | HR9: 0.016561488 | HS9: 0.016529803 | HT9: 0.016464698 | HU9: 0.016457587 | HV9: 0.016433312 | HW9: 0.016333073 | HX9: 0.016279104 | HY9: 0.016150289 | HZ9: 0.016146938 | IA9: 0.016132162 | IB9: 0.016074121 | IC9: 0.016011597 | ID9: 0.015981397 | IE9: 0.015921698 | IF9: 0.015814548 | IG9: 0.015739819 | IH9: 0.015605852 | II9: 0.015517492 | IJ9: 0.015425832 | IK9: 0.01524793 | IL9: 0.015131456 | IM9: 0.015134489 | IN9: 0.015001615 | IO9: 0.014887961 | IP9: 0.014813848 | IQ9: 0.014717832 | IR9: 0.014605287 | IS9: 0.014480127 | IT9: 0.01438047 | IU9: 0.014238758 | IV9: 0.014057902 | IW9: 0.013914931 | IX9: 0.013737081 | IY9: 0.013559963 | IZ9: 0.01338119 | JA9: 0.013198866 | JB9: 0.01297226 | JC9: 0.012775139 | JD9: 0.012637063 | JE9: 0.01252615 | JF9: 0.012420126 | JG9: 0.012359862 | JH9: 0.012309371 | JI9: 0.012316582 | JJ9: 0.01230758 | JK9: 0.012295131 | JL9: 0.012260694 | JM9: 0.012208725 | JN9: 0.0120806 | JO9: 0.01192248 | JP9: 0.011743764 | JQ9: 0.011522471 | JR9: 0.011242695 | JS9: 0.010927917 | JT9: 0.010651378 | JU9: 0.010372437 | JV9: 0.0099968481 | JW9: 0.0096220011 | JX9: 0.009233082 | JY9: 0.0088456755 | JZ9: 0.0085570356 | KA9: 0.0082648013 | KB9: 0.0080424788 | KC9: 0.007841683 | KD9: 0.0077082936 | KE9: 0.0076661663 | KF9: 0.0076454165 | KG9: 0.007681325 | KH9: 0.0077546238 | KI9: 0.0079170226 | KJ9: 0.0081247656 | KK9: 0.0084688276 | KL9: 0.0090578269 | KM9: 0.0097775303 | KN9: 0.010898027 | KO9: 0.012089673 | KP9: 0.013686757 | KQ9: 0.015210425 | KR9: 0.016779724 | KS9: 0.018368898 | KT9: 0.019836793 | KU9: 0.021938474 | KV9: 0.023257221
